<?xml version='1.0'?>
<sdf version='1.6'>
    <model name="picar">
        <static>false</static>


        <link name="chassis">
            <inertial>
                <mass>2</mass>
            </inertial>
            <pose>-0.02 0.0 0.07 0 0 0</pose>

            <collision name="chassis_collision">
                <geometry>
                    <box>
                        <size>0.18 0.07 0.04</size>
                    </box>
                </geometry>
            </collision>

            <visual name="chassis_visual">
                <geometry>
                    <box>
                        <size>0.18 0.07 0.04</size>
                    </box>
                </geometry>
            </visual>

            <collision name="caster_collision">
                <pose>-0.07 0 -0.06 0 0 0</pose>
                <geometry>
                    <sphere>
                        <radius>.01</radius>
                    </sphere>
                </geometry>

                <surface>
                    <friction>
                        <ode>
                            <mu>0</mu>
                            <mu2>0</mu2>
                            <slip1>1.0</slip1>
                            <slip2>1.0</slip2>
                        </ode>
                    </friction>
                </surface>
            </collision>

            <visual name="caster_visual">
                <pose>-0.07 0 -0.06 0 0 0</pose>
                <geometry>
                    <sphere>
                        <radius>0.01</radius>
                    </sphere>
                </geometry>
            </visual>
        </link>


    <link name="left_wheel">
        <inertial>
            <mass>0.1</mass>
        </inertial>

        <pose>0 0.05 0.032 1.5708 0 0</pose>

        <collision name="left_wheel_collision">
            <geometry>
                <cylinder>
                    <radius>0.032</radius>
                    <length>0.025</length>
                </cylinder>
            </geometry>
        </collision>

        <visual name="left_wheel_visual">
            <geometry>
                <cylinder>
                    <radius>0.032</radius>
                    <length>0.025</length>
                </cylinder>
            </geometry>
        </visual>

    </link>


    <link name="right_wheel">
        <inertial>
            <mass>0.1</mass>
        </inertial>
        <pose>0 -0.05 0.032 1.5708 0 0</pose>

        <collision name="right_wheel_collision">
            <geometry>
                <cylinder>
                    <radius>0.032</radius>
                    <length>0.025</length>
                </cylinder>
            </geometry>
        </collision>

        <visual name="right_wheel_visual">
            <geometry>
                <cylinder>
                    <radius>0.032</radius>
                    <length>0.025</length>
                </cylinder>
            </geometry>
        </visual>

    </link>


    <joint type="revolute" name="left_wheel_joint">
        <parent>chassis</parent>
        <child>left_wheel</child>
        <axis>
            <xyz>0 1 0</xyz>
            <use_parent_model_frame>1</use_parent_model_frame>
        </axis>
    </joint>


    <joint type="revolute" name="right_wheel_joint">
        <parent>chassis</parent>
        <child>right_wheel</child>
        <axis>
            <xyz>0 1 0</xyz>
            <use_parent_model_frame>1</use_parent_model_frame>
        </axis>
    </joint>


    <link name="camera_link">
        <inertial>
            <mass>0.01</mass>
        </inertial>
        <pose>0.064 0 0.11 0 0.2 0</pose>
        <sensor name="picamera" type="camera">
            <camera name="head">
                <horizontal_fov>2.094</horizontal_fov>
                <image>
                    <width>640</width>
                    <height>480</height>
                    <format>R8G8B8</format>
                </image>
                <clip>
                    <near>0.02</near>
                    <far>100</far>
                </clip>
                <noise>
                    <type>gaussian</type>
                    <mean>0.0</mean>
                    <stddev>0.007</stddev>
                </noise>
                <distortion>
                    <k1>0.0</k1>
                    <k2>0.0</k2>
                    <p1>0.0</p1>
                    <p2>0.0</p2>
                    <k3>0</k3>
                </distortion>

                <lens>
                    <type>equidistant</type>
                    <scale_to_hfov>false</scale_to_hfov>
                </lens>
            </camera>
            <always_on>1</always_on>
            <update_rate>30</update_rate>
            <visualize>1</visualize>

            <plugin name="camera_controller" filename="libgazebo_ros_camera.so">
                <alwaysOn>1</alwaysOn>
                <updateRate>0.0</updateRate>
                <cameraName>picamera</cameraName>
                <imageTopicName>image</imageTopicName>
                <distortionK1>0.0</distortionK1>
                <distortionK2>0.0</distortionK2>
                <distortionT1>0.0</distortionT1>
                <distortionT2>0.0</distortionT2>
            </plugin>
        </sensor>
    </link>

    <joint type="fixed" name="camera_joint">
        <child>camera_link</child>
        <parent>chassis</parent>
    </joint>


    <plugin name="differential_drive_controller" filename="libgazebo_ros_diff_drive.so">
        <alwaysOn>true</alwaysOn>
        <legacyMode>false</legacyMode>
        <updateRate>30</updateRate>
        <leftJoint>left_wheel_joint</leftJoint>
        <rightJoint>right_wheel_joint</rightJoint>
        <wheelSeparation>0.01</wheelSeparation>
        <wheelDiameter>0.064</wheelDiameter>
        <torque>20</torque>
        <commandTopic>cmd_vel</commandTopic>
        <odometryTopic>odom</odometryTopic>
        <odometryFrame>odom</odometryFrame>
    </plugin>

    </model>
</sdf>
